{"errorMessage": "An error occurred (AccessDenied) when calling the ListUsers operation: User: arn:aws:sts::485147667400:assumed-role/trnpreproduction-use1-Dev-User-Credentials-exec-role/trnpreproduction-use1-Dev-User-Credentials is not authorized to perform: iam:ListUsers on resource: arn:aws:iam::485147667400:user/ because no identity-based policy allows the iam:ListUsers action", "errorType": "ClientError", "requestId": "b13a4380-65db-4992-9a08-2c53b4c84091", "stackTrace": ["  File \"/var/task/lambda_handler.py\", line 10, in lambda_handler\n    users = iam.list_users()['Users']\n", "  File \"/opt/python/botocore/client.py\", line 595, in _api_call\n    return self._make_api_call(operation_name, kwargs)\n", "  File \"/opt/python/botocore/context.py\", line 123, in wrapper\n    return func(*args, **kwargs)\n", "  File \"/opt/python/botocore/client.py\", line 1058, in _make_api_call\n    raise error_class(parsed_response, operation_name)\n"]}